Workbook
Name a: #REF!
Name a_design: #REF!
Name a_design_date: #REF!
Name a_design_resp: #REF!
Name a_man: #REF!
Name a_man_date: #REF!
Name a_man_resp: #REF!
Name a_val: #REF!
Name a_val_date: #REF!
Name a_val_resp: #REF!
Name aaaaa: #REF!
Name actions_col: #REF!
Name author_col: VersionControl!$C$1
Name AUTO_MACRO: #REF!
Name block_descript: 'Block Template'!$C$1
Name block_faceid: 'Block Template'!$D$1
Name block_item: 'Block Template'!$B$1
Name cause_col: #REF!
Name changcolco: #REF!
Name change_col: #REF!
Name cir: #REF!
Name circle: #REF!
Name class_col: #REF!
Name compDate: #REF!
Name count_col: Inputs!$A$4
Name d: #REF!
Name date: #REF!
Name date_col: VersionControl!$A$1
Name date1: #REF!
Name DE_row: #REF!
Name def_r2: #REF!
Name def_row: #REF!
Name descript: #REF!
Name descript_col: VersionControl!$D$1
Name designcontrolD_col: #REF!
Name designcontrolP_col: #REF!
Name det_col: #REF!
Name det_def_col: #REF!
Name det_rating_col: #REF!
Name DFMEA_DRBFM: #REF!
Name diamond: #REF!
Name drbfm_engine: #REF!
Name DRBFM_row: #REF!
Name drbfm_trans: #REF!
Name drbfmNo: #REF!
Name effect_col: #REF!
Name effect_def_col: #REF!
Name effect_rating_col: #REF!
Name end_col: #REF!
Name eval_col: #REF!
Name first_col: Inputs!$A$4
Name first_row: 'Block Template'!$A$2
Name fmode_col: #REF!
Name function_col: #REF!
Name grpComponent: #REF!
Name inputs_descript_col: Inputs!$C$4
Name inputs_item_col: Inputs!$B$4
Name inputs_last_col: Inputs!$D$4
Name inputs_provider_col: Inputs!$D$4
Name item_col: Inputs!$B$4

Sheet VersionControl
A1: Date | B1: Version # | C1: Author of Change | D1: Description of Change | H1: Valid Admins
A2: 39780 | B2: 1

Sheet Block Template
B1: ITEM | C1: DESCRIPTION | D1: FaceID
A2: First Row: | C2: Block with label | D2: 139 | E2: 7869 | F2: 551 | G2: 662
C3: Block | D3: 131 | K3: Block (shaded) with Label | L3: 6851 | M3: 661
C4: Line | D4: 130
C5: Clearance | D5: 2234
C6: Connector | D6: 1538 | E6: 516
C7: Component (out of scope) | D7: 1851 | K7: Old one
C8: Oval with Label | D8: 720 | E8: 202 | F8: 446 | G8: 7081
C9: Oval | D9: 152 | E9: 1119 | F9: 9711
C10: Relative Motion | D10: 6527
C11: Connection Blank Label | D11: 492 | H11: # and Description - Connection
C12: ="Connection " &#REF! & " - " &#REF! | D12: 3777 | E12: 1 | H12: =REPLACE(F12,1,11,"")
C13: ="Connection " &#REF! & " - " &#REF! | D13: 3778 | E13: 2 | H13: =REPLACE(F13,1,11,"")
C14: ="Connection " &#REF! & " - " &#REF! | D14: 3779 | E14: 3 | H14: =REPLACE(F14,1,11,"")
C15: ="Connection " &#REF! & " - " &#REF! | D15: 3780 | E15: 4 | H15: =REPLACE(F15,1,11,"")
C16: ="Connection " &#REF! & " - " &#REF! | D16: 3781 | E16: 5 | H16: =REPLACE(F16,1,11,"")
C17: ="Connection " &#REF! & " - " &#REF! | D17: 3782 | E17: 6 | H17: =REPLACE(F17,1,11,"")
C18: ="Connection " &#REF! & " - " &#REF! | D18: 3783 | E18: 7 | H18: =REPLACE(F18,1,11,"")
C19: ="Connection " &#REF! & " - " &#REF! | D19: 3784 | E19: 8 | H19: =REPLACE(F19,1,11,"")
C20: ="Connection " &#REF! & " - " &#REF! | D20: 3785 | E20: 9 | H20: =REPLACE(F20,1,11,"")
C21: ="Connection " &#REF! & " - " &#REF! | D21: 3786 | E21: 10 | H21: =REPLACE(F21,1,11,"")
A36: Last Row

Sheet Inputs
A1: =IF(descript="","Description: Enter in Header Info",CONCATENATE("Description: ",descript))
A4: # | B4: Inputs | C4: Description | D4: Provider

Sheet Outputs
B1: Description: | C1: =IF(descript="","",descript)
E3: Text Prefix
A4: # | B4: Outputs | C4: Recipient(s) | D4: Output Functions | E4: System designed to

Sheet 封面
E1: 一次性胰胆成像导管过程失效模式及后果分析（PFMEA)（G06 欧盟） Single-use Video Pancreaticobiliary Scope PFMEA （G06 EU） | K1: File No. 文件编号 | L1: TM-0001083
K2: Rev: 版本 | L2: A/1
K3: Date: 日期 | L3: 46090
A11: 一次性胰胆成像导管过程失效模式及后果分析（PFMEA)（G06 欧盟） Single-use Video Pancreaticobiliary Scope PFMEA （G06 EU）

Sheet 产品适用表 
C1: =封面!E1 | G1: File No. 文件编号 | H1: =封面!L1
G2: Rev: 版本 | H2: =封面!L2
G3: Date: 日期 | H3: =封面!L3
A4: 序号No. | B4: 规格型号Specifications and models | C4: 内控号internal control number | D4: 线缆cable | E4: 器械通道直径（D1·mm）Instrument channel width | F4: 有效工作长度（L1·mm）Working length | G4: 最大插入部外径(mm）Maximum insertion portion width | H4: 软管外径(mm) Insertion tube width
A5: 1 | B5: G06001 | C5: EUG06001 | D5: 一体Integrated cable | E5: ≥2.5 | F5: 600±15 | G5: ≤5.4 | H5: 4.7±0.2
A6: 2 | B6: G06002 | C6: EUG06002 | D6: 一体Integrated cable | E6: ≥2.2 | F6: 600±15 | G6: ≤4.4 | H6: 3.9±0.2
A7: 3 | B7: G06003 | C7: EUG06003 | D7: 一体Integrated cable | E7: ≥2.2 | F7: 400±10 | G7: ≤4.4 | H7: 3.9±0.2
A8: 4 | B8: G06004 | C8: EUG06004 | D8: 一体Integrated cable | E8: ≥2.8 | F8: 600±15 | G8: ≤5.6 | H8: 5.0±0.2
A9: 5 | B9: G06005 | C9: EUG06005 | D9: 一体Integrated cable | E9: ≥2.5 | F9: 400±10 | G9: ≤5.4 | H9: 4.7±0.2
A10: 6 | B10: G06006 | C10: EUG06006 | D10: 一体Integrated cable | E10: ≥1.2 | F10: 600±15 | G10: ≤3.2 | H10: 2.8±0.2
A11: 7 | B11: G06007 | C11: EUG06007 | D11: 一体Integrated cable | E11: ≥1.2 | F11: 400±10 | G11: ≤3.2 | H11: 2.8±0.2
A12: 8 | B12: G06008 | C12: EUG06008 | D12: 一体Integrated cable | E12: ≥2.8 | F12: 400±10 | G12: ≤5.6 | H12: 5.0±0.2
A13: 9 | B13: G06009 | C13: EUG06009 | D13: 分体Split cable | E13: ≥2.5 | F13: 600±15 | G13: ≤5.4 | H13: 4.7±0.2
A14: 10 | B14: G06010 | C14: EUG06010 | D14: 分体Split cable | E14: ≥2.2 | F14: 600±15 | G14: ≤4.4 | H14: 3.9±0.2
A15: 11 | B15: G06011 | C15: EUG06011 | D15: 分体Split cable | E15: ≥2.2 | F15: 400±10 | G15: ≤4.4 | H15: 3.9±0.2
A16: 12 | B16: G06012 | C16: EUG06012 | D16: 分体Split cable | E16: ≥2.8 | F16: 600±15 | G16: ≤5.6 | H16: 5.0±0.2
... A20: 16 | B20: G06016 | C20: EUG06016 | D20: 分体Split cable | E20: ≥2.8 | F20: 400±10 | G20: ≤5.6 | H20: 5.0±0.2

Sheet PFMEA-合并
E1: =封面!E1 | M1: File No. 文件编号 | N1: =封面!L1
M2: Rev: 版本 | N2: =封面!L2
M3: Page of 第 页/共 页 | N3: 第 3 页 / 共 14 页
A4: 序号 N0. | B4: 过程名称 Process Name | C4: 功能要求 Functional requirements | D4: 潜在失效模式 FMEA | E4: 潜在失效后果 Potential Effect of Failure | F4: 严重度 severity | G4: 潜在失效起因/机理 Potential failure causes/mechanisms | H4: 频度 frequency | I4: 现行过程控制 Current process control | K4: 探测度 detectivity | L4: 风险顺序数 Risk order number | M4: 建议的纠正/预防措施 Suggested corrective/preventive measures | N4: 责任部门 Dept. | O4: 改进后 Improved
F5: S | H5: O | I5: 预防 Prevent | J5: 探测 Detection | K5: D | L5: RPN | O5: 措施实施 Implementation of measures | P5: S | Q5: O | R5: D | S5: RPN
A6: 1 | B6: 清洗 cleaning | C6: 1.清洗烘干后的物料表面干净，光洁，无残留杂质，无水渍 2.初始污染菌符合要求 3.清洗后的纯化水电导率、PH、TOC符合纯化水标准 1. The surface of the material after washing and drying is clean, smooth, without residual impurities, no water stains 2. The initial contamination bacteria meet the requirements 3. Conductivity, PH, TOC of purified water after cleaning meets the standard of purified water. | D6: 1.表面有杂质或水渍残留 2.初始污染菌超标 1. Surface with impurities or water residue 2. Initial contamination bacteria exceed the standard | E6: 1、可能导致病人感染 1. May lead to patient infections | F6: 3 | G6: 1.清洗设备损坏，导致清洗效果下降 2.一次清洗的物料超出规定的数量 3.清洗参数不合理 1. Cleaning equipment damage, resulting in reduced cleaning effect 2. A cleaning material exceeds the specified quantity 3. Cleaning parameters are not reasonable | H6: 3 | I6: 1.设备使用前进行点检 2.工艺规程中明确最大清洗数量 3.工艺规程中明确清洗参数及注意事项 1. Point inspection before the use of equipment 2. Specify the maximum number of cleaning in the process regulations 3. Clear cleaning parameters and precautions in the process regulations | J6: 1.目视外观；使用无尘布擦拭，观察无尘布有无脏污 2.在清洗确认中展开酸碱度检测和初始污染菌检测。 1. Visualize the appearance; use a dust-free cloth to wipe and observe whether the dust-free cloth is dirty or not 2. Expand the acidity and alkalinity test and initial contamination bacteria test in the cleaning confirmation. | K6: 4 | L6: 24 | M6: 关键工序 特殊工序 进行清洗验证或清洗评估 Critical Processes Specialized processes Perform cleaning validation or cleaning assessment | N6: 可视化研发部 Visualization R&D Department | O6: MTN-1007620一次性胰胆成像导管OQ评估报告 MTN-1007620 OQ assessment Report for Single-use Video Pancreaticobiliary Scope | P6: 3 | Q6: 1 | R6: 4 | S6: 12
A7: 2 | B7: 散热片组装 Heat sink assembly | C7: 光学性能满足要求Optical performance meets requirements | D7: 1.集束管未到达指定位置； 2.LED灯损坏 3.LED松动 1. The cluster tube does not reach the designated position; 2.LED is damaged 3.LED loose | E7: 1.光通量无法满足； 2.LED不亮或者灯光颜色不正常 1. Luminous flux cannot be satisfied; 2.LED does not light up or the light color is not normal | F7: 3 | G7: 1.集束管未安装到底； 2.LED安装时受损 3.螺纹松动 1. The cluster tube is not installed to the bottom; 2.LED damaged during installation 3. Loose threads | H7: 2 | I7: 1.安装后确认集束管台阶面是否与散热片端面贴合； 2.LED安装前检查灯粉无脱落/不亮现象，安装过程中避免接触灯粉位置3.安装前确认螺纹要拧紧 1. After installation, make sure that the step surface of the cluster tube fits the end surface of the heat sink; 2. Check that the lamp powder does not fall off/not bright before LED installation, and avoid contacting the lamp powder position during installation 3. Confirm that the threads should be tightened before installation | J7: 1.目视全检； 2.连接成像控制器，确认LED灯板发光是否正常； 3.检查灯板，螺钉有无晃动 1. Visualize the whole inspection; 2. Connect the imaging controller to confirm that the LED light board emits light normally; 3. Check the light board, screws with or without shaking | K7: 2 | L7: 12 | M7: 无 none | N7: / | O7: / | P7: / | Q7: / | R7: / | S7: /
A8: 3 | B8: 模组地线焊接 Module Ground Soldering | C8: 1.产品能正常显示图像 2.模组线焊接处UV胶覆盖完全 1.The product can display the image normally 2.The UV adhesive covers the welding of the module line completely. | D8: 产品不能成像，或成像异常 Product cannot be imaged, or is imaged abnormally | E8: 1.下道工序中断 2.产品不能成像，用户非常不满 1. the next process is interrupted 2. the product cannot be imaged and the user is very dissatisfied | F8: 3 | G8: 1.镜头线焊接有虚焊，焊接线序错误，焊接手法不明确 2.剥线损伤线芯 1. Lens wire welding with false welding, welding line sequence error, welding method is not clear 2. Stripping damage to the core | H8: 2 | I8: 工艺明确焊接线序、焊接后的检查方法，同时明确焊接操作 The process specifies the welding line sequence, the inspection method after welding, and also specifies the welding operation. | J8: 将焊接后的插接头连接图像测试工装，观察是否有图像、是否异常，目视全检 Connect the welded plug connector to the image test tooling, observe whether there is an image, whether there is any abnormality, visual full inspection | K8: 2 | L8: 12 | M8: 关键工序 Key processes | N8: 可视化研发部 Visualization R&D Department | O8: MTN-1007620一次性胰胆成像导管OQ评估报告 MTN-1007620 OQ assessment Report for Single-use Video Pancreaticobiliary Scope | P8: 3 | Q8: 1 | R8: 2 | S8: 6
D9: 焊接处无UV胶覆盖或覆盖量很少 UV胶未固化 No or very little UV adhesive coverage on the weld. UV adhesive not cured | F9: 2 | G9: 文件未规定UV胶覆盖状态 Documentation does not specify UV adhesive coverage status | I9: 工艺明确UV胶覆盖要求，选用合理的固化参数 Process clear UV adhesive coverage requirements, the selection of reasonable curing parameters | J9: 目视全检，并手触UV胶覆盖处不发粘 Visual inspection and hand-touching of the UV adhesive cover for non-stickiness | K9: 2 | L9: 8 | M9: 无 none | N9: / | O9: / | P9: / | Q9: / | R9: / | S9: /
C10: 编制网管、限位块与TYPC接通 Preparation of reticule, limit block and TYPC connection | D10: 虚焊或热缩管未套紧 False soldering or heat shrink tubing not tightened | E10: 输出视频信号不稳定 Unstable output video signal | F10: 2 | G10: 出现虚焊现象 Void soldering occurs | H10: 1 | I10: 增加自检：轻拉不脱落，热缩护套管覆盖焊接位置且无滑动 Increased self-testing: light pulling does not detach, heat-shrinkable tubing covers the weld position without slipping | J10: 全检焊接位置是否全覆盖，热缩管不滑动，轻拉不脱落 Full inspection of the welding position for full coverage, heat shrink tubing does not slide, light pull does not fall off | K10: 2 | L10: 4 | M10: 无 none | N10: / | O10: / | P10: / | Q10: / | R10: / | S10: /
A11: 4 | B11: 下壳组件安装 Lower Shell Assembly Installation | C11: 1.器械钳道能通过对应规格导丝 2.吸引阀工作正常，吸引，注液不泄露 3.液路管连接的阀体、吸引管、Y型三通安装位置正确 4.成像导管相对手柄不转动 1. The instrument clamp channel can pass through the corresponding specification guidewire. 2. The suction valve is working properly, and there is no leakage of suction and liquid injection. 3. The valve body, suction tube and Y-type tee connected to the liquid line are installed in the correct position. 4. The imaging catheter does not rotate relative to the handle. | D11: 器械腔道变形 Instrument lumen deformation | E11: 器械无法顺利通过 The instruments can't get through. | F11: 3 | G11: 器械腔道与Y型三通连接处挤压变形 Extruded deformation of instrument lumen and Y-type tee connection | H11: 2 | I11: 安装时用对应规格的芯轴插入钳道管支撑 When installing, insert an arbor of the corresponding size into the support of the clamp pipe. | J11: 安装后用对应规格导丝全检 Full inspection with corresponding specification guidewire after installation | K11: 2 | L11: 12 | M11: 无 none | N11: / | O11: / | P11: / | Q11: / | R11: / | S11: /
D12: 1.吸引和注液时泄漏 2.液路管扭曲严重，影响吸液量 3.成像导管在手柄上松动，可转动 1. Leakage during suction and injection 2. Liquid line tube is badly twisted, affecting suction volume 3. Imaging catheter is loose on the handle and can be rotated | E12: 1.可能导致病人感染 2.吸引功能下降 3.手柄与成像导管旋转同步性不好 1. May lead to patient infection 2. Decreased suction function 3. Poor synchronization of handle and imaging catheter rotation | F12: 4 | G12: 1.胶水未涂到位，或固化参数不合理 2.液路管两侧零件安装相对位置不正确，液路管长度过长 3.压板未压紧 1. The glue is not coated in place, or the curing parameters are unreasonable. 2. The relative positions of the parts installed on both sides of the liquid line pipe are not correct, and the length of the liquid line pipe is too long. 3. Pressure plate is not pressed tightly | H12: 2 | I12: 1.固化后确认胶水是否整圈涂覆上去，选用合理的固化参数 2.明确液路管两侧零件的方向，制定合理液路管的尺寸 3.螺钉安装至旋不动为止，并在导管与压板贴合端面涂UV胶固化 1. After curing, make sure the glue is coated on the whole circle, and choose reasonable curing parameters. 2. Clearly define the direction of the parts on both sides of the liquid line pipe, and make reasonable size of the liquid line pipe. 3. Install the screws until they do not move, and apply UV adhesive to the end surface of the tube and the pressure plate for curing. | J12: 1.气密性检测 2.目视液路管有无严重扭曲弯折现象 3.安装前用钢尺确认液路管尺寸 4.轻微转动导管，确认导管相对手柄不转动 1. Gas tightness test 2. Visual inspection of the liquid line pipe for serious twisting and bending phenomenon 3. Confirm the size of the liquid line pipe with a steel ruler before installation. 4. Slightly rotate the tube to make sure that the tube does not rotate relative to the handle. | K12: 2 | L12: 8 | M12: 无 none | N12: / | O12: / | P12: / | Q12: / | R12: / | S12: /
E13: =封面!E1 | M13: File No. 文件编号 | N13: =封面!L1
M14: Rev: 版本 | N14: =封面!L2
M15: Page of 第 页/共 页 | N15: 第 4 页 / 共 14 页
A16: 序号 N0. | B16: 过程名称 Process Name | C16: 功能要求 Functional requirements | D16: 潜在失效模式 FMEA | E16: 潜在失效后果 Potential Effect of Failure | F16: 严重度 severity | G16: 潜在失效起因/机理 Potential failure causes/mechanisms | H16: 频度 frequency | I16: 现行过程控制 Current process control | K16: 探测度 detectivity | L16: 风险顺序数 Risk order number | M16: 建议的纠正/预防措施 Suggested corrective/preventive measures | N16: 责任部门 Dept. | O16: 改进后 Improved
F17: S | H17: O | I17: 预防 Prevent | J17: 探测 Detection | K17: D | L17: RPN | O17: 措施实施 Implementation of measures | P17: S | Q17: O | R17: D | S17: RPN
A18: 5 | B18: 转轮组装 Rotor assembly | C18: 1.牵引丝与固定头连接力≥15N 2.转向无空行程；3.中位情况下外包覆层无严重褶皱（保证相应规格的量具测量满足要求） 4、转向方向正确，角度合格 1. Traction wire and fixed head connection force ≥ 15N 2. Steering without empty stroke; 3. No serious wrinkles in the outer cladding layer in the case of neutral (to ensure that the corresponding specifications of the gauge measurement to meet the requirements) 4. Correct steering direction and qualified angle | D18: 1、固定管脱落 2、牵引丝未绷紧；3.蛇骨受压严重 1. The fixation tube is dislodged 2. Traction wire not taut; 3. Serpentine bone severely compressed | E18: 1.下道工序中断 2.产品转向功能失效，用户非常不满；3.弯曲部外径超差。 1. Interruption of the next process 2. Failure of the steering function of the product, the user is very dissatisfied; 3. Bending part of the outer diameter exceeds the difference. | F18: 3 | G18: 1.铆接直径不对或者无按压到位； 2.张紧螺钉盘的牵引丝过少； 3.张紧螺钉盘的牵引丝过多； 4.反向螺母未拧紧 1. Incorrect riveting diameter or no press in place; 2. Too few traction wires in the tensioning screw disk; 3. Too much traction wire on the tensioning screw disk; 4. The reverse nut is not tightened. | H18: 2 | I18: 1.通过验证选取合适的参数，并要求每次启动时进行核对、点检 2和3设计专用工装 4.安装反向螺母直到扳手拧不动为止 1. Select the appropriate parameters through verification and require checking and spot-checking at each startup 2 and 3 design special tooling 4. Installation of the reverse nut until the wrench is not able to unscrew it. | J18: 1.每次使用前点检铆接钳的铆接直径 2.使用拉力机测试固定管和牵引丝的首件拉力 3.确认反向螺母是否锁紧 1. Check the riveting diameter of riveting pliers before each use. 2. Use the tension machine to test the first piece of tension of the fixed tube and traction wire 3. Make sure the reverse nut is locked. | K18: 4 | L18: 24 | M18: 关键工序 特殊工序 进行铆接确认 Critical Processes Special Processes Confirmation of riveting | N18: 可视化研发部 Visualization R&D Department | O18: MTN-1007620一次性胰胆成像导管OQ评估报告 MTN-1007620 OQ assessment Report for Single-use Video Pancreaticobiliary Scope | P18: 3 | Q18: 1 | R18: 4 | S18: 12
A19: 6 | B19: 上壳手柄组装 Upper shell handle assembly | C19: 1、手柄能控制远端软头上下转动 2、按键帽回弹正常3、上下壳美工缝均匀，上下壳无明显间隙 1, the handle can control the distal end of the soft head up and down rotation 2、Key cap rebound normal 3、Upper and lower shell without obvious gap | D19: 手柄不能控制远端软头上下转动 Handle does not control up and down rotation of the distal soft head | E19: 产品性能下降，用户非常不满 Product performance degradation, users are very dissatisfied | F19: 3 | G19: 螺钉未安装到位 Screws not in place | H19: 2 | I19: 工艺未明确螺钉安装位置 Process does not specify screw mounting locations | J19: 目视全检螺钉是否埋入拨杆，并转动手轮检查 Visually check that the full inspection screws are buried in the toggle and turn the handwheel to check | K19: 2 | L19: 12 | M19: 无 none | N19: / | O19: / | P19: / | Q19: / | R19: / | S19: /
D20: 按键不能回弹 Buttons don't return | E20: 产品截图/冻结功能失效，用户非常不满 Product screenshot/freeze function not working, users very upset | F20: 3 | G20: PCB板装配位置不正确 Incorrect PCB board assembly position | H20: 1 | I20: 工艺明确安装位置 The process specifies the location of the installation | J20: 连接成像控制器，确认冻结/截图功能是否正常 Connect the imaging controller and verify that the freeze/screenshot function is working properly | K20: 2 | L20: 6 | M20: 无 none | N20: / | O20: / | P20: / | Q20: / | R20: / | S20: /
D21: 上下壳间隙过大 Excessive clearance between upper and lower housing | E21: 客户不满意 Customer dissatisfaction | F21: 2 | G21: 上壳未安装到位 Upper housing not in place | H21: 2 | I21: 工艺增加自检 Process increase self-testing | J21: 目视全检 visual inspection | K21: 2 | L21: 8 | M21: 无 none | N21: / | O21: / | P21: / | Q21: / | R21: / | S21: /
A22: 7 | B22: 过程检 Process inspection | C22: N/A
A23: 8 | B23: 完工检 Finish inspection | C23: N/A
A24: 9 | B24: 打印标签 Print Labels | C24: 根据产品DHR信息进行标签打印。 Label printing based on product DHR information. | D24: 标签打印模糊 Label printing obscured. | E24: 信息不全，使用不便，延长手术时间 Incomplete information, inconvenient use, prolonged operation time. | F24: 2 | G24: 1.打印机参数设置错误。 2.空白标签使用错误，模板使用错误。 3.打印机异常。 1.Printer parameters set incorrectly. 2.Blank label used incorrectly, template used incorrectly. 3.Printer Exception. | H24: 1 | I24: 1.对打印参数进行验证，打印机每日开班进行点检。 2.进行人员岗位培训，固定标签模板，内控号与模板有系统绑定，数据库有会签、评审。 3.打印设备定时维保。 1.Print parameters are verified and printer is spot-checked daily. 2.Performing on-the-job training for personnel, fixing label template, binding between internal control number and template, countersignature and review of database. 3.Print device timing maintenance. | J24: 1.作业人员目视检查标签品质。 2.每批标签首件确认。 3.最终检对包装后产品进行抽检。 1.Operators visually check label quality. 2.First article confirmation of each batch of labels. 3.Final inspection will spot check the packaged product. | K24: 2 | L24: 4 | M24: - | O24: - | P24: - | Q24: - | R24: - | S24: -
D25: 标签格式打印错误 Label format printed incorrectly. | O25: - | P25: - | Q25: - | R25: - | S25: -
D26: 标签打印内容错误 3.Label printed incorrectly. | E26: 错误使用器械，对患者造成损伤 Incorrect use of device causing injury to patient. | F26: 3 | G26: 1.DHR错误。 2.标签模板信息错误，标签模板选用错误。 3.打印人员信息录入错误。 1.DHR Error. 2.Label template information error,label template selection error. 3.Print person information entry error. | H26: 1 | I26: 1.对DHR进行复核确认。 2.标签模板需要进行会签确认，内控号与模板有系统绑定，数据库有会签、评审。 3.进行人员岗位培训。 1.DHR reviewed and confirmed. 2.The label template requires countersignature confirmation, and the internal control number is system-bound to the template, with the database containing countersignature and review records.. 3.Performing on-the-job training for personnel. | K26: 2 | L26: 6 | M26: 按照《标签打印及确认标准作业指导书》作业 Operate in accordance with the "Standard Operating Instruction for Label Printing and Confirmation" | O26: - | P26: 3 | Q26: 1 | R26: 1 | S26: 3
D27: UDI条码信息错误 4. UDI barcode information error | E27: 器械无法正常入成品库 Devices cannot normally enter the finished goods warehouse. | F27: 3 | G27: 1.标签模板信息错误； 2.标签模板选用错误； 1. Label template information error; 2. Label template selection error. | H27: 1 | I27: 1.标签模板需要进行会签确认，且内控号与模板有系统绑定，数据库有会签、评审。 2.进行人员岗位培训。 1.The label template requires countersignature confirmation, and the internal control number is system-bound to the template, with the database containing countersignature and review records. 2.Performing on-the-job training for personnel. | J27: 每批标签首件确认时进行UDI条码确认 Perform UDI barcode confirmation during the first article confirmation of each batch of labels. | K27: 2 | L27: 6 | M27: 按照《标签打印及确认标准作业指导书》作业 Operate in accordance with the "Standard Operating Instruction for Label Printing and Confirmation" | N27: 产品管理部 1.Product Management Department | O27: - | P27: 3 | Q27: 1 | R27: 1 | S27: 3
E28: =封面!E1 | M28: File No. 文件编号 | N28: =封面!L1
M29: Rev: 版本 | N29: =封面!L2
M30: Page of 第 页/共 页 | N30: 第 5 页 / 共 14 页
A31: 序号 N0. | B31: 过程名称 Process Name | C31: 功能要求 Functional requirements | D31: 潜在失效模式 FMEA | E31: 潜在失效后果 Potential Effect of Failure | F31: 严重度 severity | G31: 潜在失效起因/机理 Potential failure causes/mechanisms | H31: 频度 frequency | I31: 现行过程控制 Current process control | K31: 探测度 detectivity | L31: 风险顺序数 Risk order number | M31: 建议的纠正/预防措施 Suggested corrective/preventive measures | N31: 责任部门 Dept. | O31: 改进后 Improved
F32: S | H32: O | I32: 预防 Prevent | J32: 探测 Detection | K32: D | L32: RPN | O32: 措施实施 Implementation of measures | P32: S | Q32: O | R32: D | S32: RPN
A33: 10 | B33: 内包装 Inner packaging | C33: 配件完整 Fittings complete | D33: 配件缺失 Missing accessories | E33: 产品功能下降，用户非常不满 Product functionality has declined and users are very dissatisfied | F33: 3 | G33: 文件未明确配件安装位置 Documentation does not specify where accessories are to be mounted Documentation does not specify where accessories are to be mounted | H33: 2 | I33: 工艺明确配件安装位置，明确自检要求 The process clarifies the installation of accessories and self-inspection requirements | J33: 目视配件是否齐全 Visual inspection of accessories for completeness | K33: 1 | L33: 6 | M33: 无 none | N33: / | O33: / | P33: / | Q33: / | R33: / | S33: /
C34: 封口宽度不小于6mm Seal width not less than 6mm | D34: 纸塑袋破损 Broken paper-plastic bags | E34: 产品带菌，引起患者损伤 Product carries bacteria, causing patient injury | F34: 4 | G34: 设备参数不合适 Inappropriate equipment parameters | H34: 2 | I34: 1、进行包装确认 2、建立完善的设备参数 每批进行首检确认 1、Packaging confirmation 2、Establish perfect equipment parameters First inspection confirmation for each batch | J34: 1.目视全检包装有无破损 2.使用拉力机测试包装的首件拉力 1. Visually inspect the package for damage. 2. Use the tensile machine to test the first piece of packaging tension | K34: 4 | L34: 24 | M34: 关键工序 特殊工序 进行封口确认/评估 Critical Processes Special Processes Perform seal confirmation/evaluation | N34: 可视化研发部 Visualization R&D Department | O34: MTN-1007620一次性胰胆成像导管OQ评估报告 MTN-1007620 OQ assessment Report for Single-use Video Pancreaticobiliary Scope | P34: 4 | Q34: 1 | R34: 4 | S34: 12
C35: 封口剥离强度≥1.0 lbf/inch Seal peel strength ≥1.0 lbf/inch
A36: 11 | B36: 外包装 Outer packaging | C36: 按规定数量进行中盒和外箱的包装，并放入产品说明书 Packing of the center box and outer box according to the specified quantity, and putting in the product manuals | D36: 说明书缺失 Missing instructions | E36: 1.下道工序中断 2.用户非常不满 1. Interruption of the next process 2. Very dissatisfied users | F36: 3 | G36: 包装要求不明确 Unclear packaging requirements | H36: 2 | I36: 明确工艺过程自检要求 Clarify process self-inspection requirements | J36: 目视全检 visual inspection | K36: 1 | L36: 6 | M36: 无 none | N36: / | O36: / | P36: / | Q36: / | R36: / | S36: /
D37: 包装方式错误 Wrong type of packaging | E37: 1.下道工序中断 2.用户非常不满 1. Interruption of the next process 2. Very dissatisfied users | N37: / | O37: / | P37: / | Q37: / | R37: / | S37: /
A38: 12 | B38: 最终检 Final inspection | C38: N/A
A39: 13 | B39: 灭菌 sterilization | C39: 保证产品为无菌状态 Ensure that the product is sterile | D39: 产品带菌 Product Sterilization | E39: 引起患者损伤 Causes injury to the patient | F39: 4 | G39: 灭菌参数不正确 Incorrect sterilization parameters | H39: 2 | I39: 1.进行灭菌确认 2.对每个灭菌批产品进行BI检测，同时对灭菌批记录进行核对，外包和内包全数贴灭菌标签预防遗漏 1. Perform sterilization confirmation 2. Perform BI test on each sterilized batch of products, check the records of sterilized batch at the same time, and label all the outsourced and insourced products with sterilized labels to prevent omission. | J39: 目视全检 无菌测试 Visual inspection Aseptic testing | K39: 4 | L39: 32 | M39: 关键工序 特殊工序 进行灭菌确认/评估 Critical Processes Special processes Sterilization confirmation/assessment | N39: 可视化研发部 Visualization R&D Department | O39: MTN-1010340 一次性胰胆成像导管 EO 灭菌过程评估报告 MTN-1010340 EO-Sterilization Process Evaluation Report of Single-use Video Pancreaticobiliary Scope | P39: 4 | Q39: 1 | R39: 4 | S39: 16
A40: 14 | B40: 出厂检 Delivery inspection | C40: N/A
...

Sheet PFMEA -英文
E1: Single-use Video Pancreaticobiliary Scope PFMEA （G06 EU） | M1: File No. | N1: =封面!L1
M2: Rev: | N2: =封面!L2
M3: Page of | N3: Page 6 of 14
A4: N0. | B4: Process Name | C4: Functional requirements | D4: FMEA | E4: Potential Effect of Failure | F4: severity | G4: Potential failure causes/mechanisms | H4: frequency | I4: Current process control | K4: detectivity | L4: Risk order number | M4: Suggested corrective/preventive measures | N4: Dept. | O4: Improved
F5: S | H5: O | I5: Prevent | J5: Detection | K5: D | L5: RPN | O5: Implementation of measures | P5: S | Q5: O | R5: D | S5: RPN
A6: 1 | B6: cleaning | C6: 1. The surface of the material after washing and drying is clean, smooth, without residual impurities, no water stains 2. The initial contamination bacteria meet the requirements 3. Conductivity, PH, TOC of purified water after cleaning meets the standard of purified water. | D6: 1. Surface with impurities or water residue 2. Initial contamination bacteria exceed the standard | E6: 1. May lead to patient infections | F6: 3 | G6: 1. Cleaning equipment damage, resulting in reduced cleaning effect 2. A cleaning material exceeds the specified quantity 3. Cleaning parameters are not reasonable | H6: 3 | I6: 1. Point inspection before the use of equipment 2. Specify the maximum number of cleaning in the process regulations 3. Clear cleaning parameters and precautions in the process regulations | J6: 1. Visualize the appearance; use a dust-free cloth to wipe and observe whether the dust-free cloth is dirty or not 2. Expand the acidity and alkalinity test and initial contamination bacteria test in the cleaning confirmation. | K6: 4 | L6: 24 | M6: Critical Processes Specialized processes Perform cleaning validation or cleaning assessment | N6: Visualization R&D Department | O6: MTN-1007620 OQ assessment Report for Single-use Video Pancreaticobiliary Scope | P6: 3 | Q6: 1 | R6: 4 | S6: 12
A7: 2 | B7: Heat sink assembly | C7: 光学性能满足要求Optical performance meets requirements | D7: 1. The cluster tube does not reach the designated position; 2.LED is damaged 3.LED loose | E7: 1. Luminous flux cannot be satisfied; 2.LED does not light up or the light color is not normal | F7: 3 | G7: 1. The cluster tube is not installed to the bottom; 2.LED damaged during installation 3. Loose threads | H7: 2 | I7: 1. After installation, make sure that the step surface of the cluster tube fits the end surface of the heat sink; 2. Check that the lamp powder does not fall off/not bright before LED installation, and avoid contacting the lamp powder position during installation 3. Confirm that the threads should be tightened before installation | J7: 1. Visualize the whole inspection; 2. Connect the imaging controller to confirm that the LED light board emits light normally; 3. Check the light board, screws with or without shaking | K7: 2 | L7: 12 | M7: none | N7: / | O7: / | P7: / | Q7: / | R7: / | S7: /
E8: Single-use Video Pancreaticobiliary Scope PFMEA （G06 EU） | M8: File No. | N8: =封面!$L$1
M9: Rev: | N9: =封面!$L$2
M10: Page of | N10: Page 7 of 14
A11: N0. | B11: Process Name | C11: Functional requirements | D11: FMEA | E11: Potential Effect of Failure | F11: severity | G11: Potential failure causes/mechanisms | H11: frequency | I11: Current process control | K11: detectivity | L11: Risk order number | M11: Suggested corrective/preventive measures | N11: Dept. | O11: Improved
F12: S | H12: O | I12: Prevent | J12: Detection | K12: D | L12: RPN | O12: Implementation of measures | P12: S | Q12: O | R12: D | S12: RPN
A13: 3 | B13: Module Ground Soldering | C13: 1.The product can display the image normally 2.The UV adhesive covers the welding of the module line completely. | D13: Product cannot be imaged, or is imaged abnormally | E13: 1. the next process is interrupted 2. the product cannot be imaged and the user is very dissatisfied | F13: 3 | G13: 1. Lens wire welding with false welding, welding line sequence error, welding method is not clear 2. Stripping damage to the core | H13: 2 | I13: The process specifies the welding line sequence, the inspection method after welding, and also specifies the welding operation. | J13: Connect the welded plug connector to the image test tooling, observe whether there is an image, whether there is any abnormality, visual full inspection | K13: 2 | L13: 12 | M13: Key processes | N13: Visualization R&D Department | O13: MTN-1007620 OQ assessment Report for Single-use Video Pancreaticobiliary Scope | P13: 3 | Q13: 1 | R13: 2 | S13: 6
D14: No or very little UV adhesive coverage on the weld. UV adhesive not cured | F14: 2 | G14: Documentation does not specify UV adhesive coverage status | I14: Process clear UV adhesive coverage requirements, the selection of reasonable curing parameters | J14: Visual inspection and hand-touching of the UV adhesive cover for non-stickiness | K14: 2 | L14: 8 | M14: none | N14: / | O14: / | P14: / | Q14: / | R14: / | S14: /
C15: Preparation of reticule, limit block and TYPC connection | D15: False soldering or heat shrink tubing not tightened | E15: Unstable output video signal | F15: 2 | G15: Void soldering occurs | H15: 1 | I15: Increased self-testing: light pulling does not detach, heat-shrinkable tubing covers the weld position without slipping | J15: Full inspection of the welding position for full coverage, heat shrink tubing does not slide, light pull does not fall off | K15: 2 | L15: 4 | M15: none | N15: / | O15: / | P15: / | Q15: / | R15: / | S15: /
E16: Single-use Video Pancreaticobiliary Scope PFMEA （G06 EU） | M16: File No. | N16: =封面!$L$1
M17: Rev: | N17: =封面!$L$2
M18: Page of | N18: Page 8 of 14
A19: N0. | B19: Process Name | C19: Functional requirements | D19: FMEA | E19: Potential Effect of Failure | F19: severity | G19: Potential failure causes/mechanisms | H19: frequency | I19: Current process control | K19: detectivity | L19: Risk order number | M19: Suggested corrective/preventive measures | N19: Dept. | O19: Improved
F20: S | H20: O | I20: Prevent | J20: Detection | K20: D | L20: RPN | O20: Implementation of measures | P20: S | Q20: O | R20: D | S20: RPN
A21: 4 | B21: Lower Shell Assembly Installation | C21: 1. The instrument clamp channel can pass through the corresponding specification guidewire. 2. The suction valve is working properly, and there is no leakage of suction and liquid injection. 3. The valve body, suction tube and Y-type tee connected to the liquid line are installed in the correct position. 4. The imaging catheter does not rotate relative to the handle. | D21: Instrument lumen deformation | E21: The instruments can't get through. | F21: 3 | G21: Extruded deformation of instrument lumen and Y-type tee connection | H21: 2 | I21: When installing, insert an arbor of the corresponding size into the support of the clamp pipe. | J21: Full inspection with corresponding specification guidewire after installation | K21: 2 | L21: 12 | M21: none | N21: / | O21: / | P21: / | Q21: / | R21: / | S21: /
D22: 1. Leakage during suction and injection 2. Liquid line tube is badly twisted, affecting suction volume 3. Imaging catheter is loose on the handle and can be rotated | E22: 1. May lead to patient infection 2. Decreased suction function 3. Poor synchronization of handle and imaging catheter rotation | F22: 4 | G22: 1. The glue is not coated in place, or the curing parameters are unreasonable. 2. The relative positions of the parts installed on both sides of the liquid line pipe are not correct, and the length of the liquid line pipe is too long. 3. Pressure plate is not pressed tightly | H22: 2 | I22: 1. After curing, make sure the glue is coated on the whole circle, and choose reasonable curing parameters. 2. Clearly define the direction of the parts on both sides of the liquid line pipe, and make reasonable size of the liquid line pipe. 3. Install the screws until they do not move, and apply UV adhesive to the end surface of the tube and the pressure plate for curing. | J22: 1. Gas tightness test 2. Visual inspection of the liquid line pipe for serious twisting and bending phenomenon 3. Confirm the size of the liquid line pipe with a steel ruler before installation. 4. Slightly rotate the tube to make sure that the tube does not rotate relative to the handle. | K22: 2 | L22: 8 | M22: none | N22: / | O22: / | P22: / | Q22: / | R22: / | S22: /
E23: Single-use Video Pancreaticobiliary Scope PFMEA （G06 EU） | M23: File No. | N23: =封面!$L$1
M24: Rev: | N24: =封面!$L$2
M25: Page of | N25: Page 9 of 14
A26: N0. | B26: Process Name | C26: Functional requirements | D26: FMEA | E26: Potential Effect of Failure | F26: severity | G26: Potential failure causes/mechanisms | H26: frequency | I26: Current process control | K26: detectivity | L26: Risk order number | M26: Suggested corrective/preventive measures | N26: Dept. | O26: Improved
F27: S | H27: O | I27: Prevent | J27: Detection | K27: D | L27: RPN | O27: Implementation of measures | P27: S | Q27: O | R27: D | S27: RPN
A28: 5 | B28: Rotor assembly | C28: 1. Traction wire and fixed head connection force ≥ 15N 2. Steering without empty stroke; 3. No serious wrinkles in the outer cladding layer in the case of neutral (to ensure that the corresponding specifications of the gauge measurement to meet the requirements) 4. Correct steering direction and qualified angle | D28: 1. The fixation tube is dislodged 2. Traction wire not taut; 3. Serpentine bone severely compressed | E28: 1. Interruption of the next process 2. Failure of the steering function of the product, the user is very dissatisfied; 3. Bending part of the outer diameter exceeds the difference. | F28: 3 | G28: 1. Incorrect riveting diameter or no press in place; 2. Too few traction wires in the tensioning screw disk; 3. Too much traction wire on the tensioning screw disk; 4. The reverse nut is not tightened. | H28: 2 | I28: 1. Select the appropriate parameters through verification and require checking and spot-checking at each startup 2 and 3 design special tooling 4. Installation of the reverse nut until the wrench is not able to unscrew it. | J28: 1. Check the riveting diameter of riveting pliers before each use. 2. Use the tension machine to test the first piece of tension of the fixed tube and traction wire 3. Make sure the reverse nut is locked. | K28: 4 | L28: 24 | M28: Critical Processes Special Processes Confirmation of riveting | N28: Visualization R&D Department | O28: MTN-1007620 OQ assessment Report for Single-use Video Pancreaticobiliary Scope | P28: 3 | Q28: 1 | R28: 4 | S28: 12
A29: 6 | B29: Upper shell handle assembly | C29: 1, the handle can control the distal end of the soft head up and down rotation 2、Key cap rebound normal 3、Upper and lower shell without obvious gap | D29: Handle does not control up and down rotation of the distal soft head | E29: Product performance degradation, users are very dissatisfied | F29: 3 | G29: Screws not in place | H29: 2 | I29: Process does not specify screw mounting locations | J29: Visually check that the full inspection screws are buried in the toggle and turn the handwheel to check | K29: 2 | L29: 12 | M29: none | N29: / | O29: / | P29: / | Q29: / | R29: / | S29: /
D30: Buttons don't return | E30: Product screenshot/freeze function not working, users very upset | F30: 3 | G30: Incorrect PCB board assembly position | H30: 1 | I30: The process specifies the location of the installation | J30: Connect the imaging controller and verify that the freeze/screenshot function is working properly | K30: 2 | L30: 6 | M30: none | N30: / | O30: / | P30: / | Q30: / | R30: / | S30: /
D31: Excessive clearance between upper and lower housing | E31: Customer dissatisfaction | F31: 2 | G31: Upper housing not in place | H31: 2 | I31: Process increase self-testing | J31: visual inspection | K31: 2 | L31: 8 | M31: none | N31: / | O31: / | P31: / | Q31: / | R31: / | S31: /
A32: 7 | B32: Process inspection | C32: N/A
A33: 8 | B33: Finish inspection | C33: N/A
E34: Single-use Video Pancreaticobiliary Scope PFMEA （G06 EU） | M34: File No. | N34: =封面!$L$1
M35: Rev: | N35: =封面!$L$2
M36: Page of | N36: Page 10 of 14
A37: N0. | B37: Process Name | C37: Functional requirements | D37: FMEA | E37: Potential Effect of Failure | F37: severity | G37: Potential failure causes/mechanisms | H37: frequency | I37: Current process control | K37: detectivity | L37: Risk order number | M37: Suggested corrective/preventive measures | N37: Dept. | O37: Improved
F38: S | H38: O | I38: Prevent | J38: Detection | K38: D | L38: RPN | O38: Implementation of measures | P38: S | Q38: O | R38: D | S38: RPN
A39: 9 | B39: Print Labels | C39: Label printing based on product DHR information. | D39: Label printing obscured. | E39: Incomplete information, inconvenient use, prolonged operation time. | F39: 2 | G39: 1.Printer parameters set incorrectly. 2.Blank label used incorrectly, template used incorrectly. 3.Printer Exception. | H39: 1 | I39: 1.Print parameters are verified and printer is spot-checked daily. 2.Performing on-the-job training for personnel, fixing label template, binding between internal control number and template, countersignature and review of database. 3.Print device timing maintenance. | J39: 1.Operators visually check label quality. 2.First article confirmation of each batch of labels. 3.Final inspection will spot check the packaged product. | K39: 2 | L39: 4 | M39: - | O39: - | P39: - | Q39: - | R39: - | S39: -
D40: Label format printed incorrectly. | O40: - | P40: - | Q40: - | R40: - | S40: -
...

Sheet 版本履历
E1: =封面!E1 | K1: File No. 文件编号 | L1: =封面!L1
K2: Rev: 版本 | L2: =封面!L2
K3: Page of 第 页/共 页 | L3: 第 14 页 / 共14 页
A4: 版本履历
A6: 序号N0. | B6: 版本Rev: | D6: 描述description | J6: 日期date | L6: 编制人/修订人Prepared by/revised by
A7: 1 | B7: A/0 | D7: 1，本文件由MTN-1007612_A0升版；This document has been upgraded from MTN-1007612-A0; 2，增加改善措施证据Increase evidence of improvement measures. | J7: 45666 | L7: 李文昌
A8: 2 | B8: A/1 | D8: 1.CR00001695: 产品DHR模版增加“标签记录-UDI 条码验证详细说明记录 “QR-0913-004-005 Rev：A/0”，PFMEA中增加“UDI条码信息错误”的潜在失效模式识别； | J8: 46087 | L8: 张洪源

Sheet Definition of Change Point's
A1: Design FMEA
A2: Potential Failure Mode and Effects Analysis
C3: Description: | I3: FMEA Number:
C4: Model Year(s):
C5: Vehicle:
A7: VPPS Level 1 | B7: VPPS Level 2 | C7: VPPS Level 3 | D7: VPPS Level 4 | E7: VPPS Level 5 | F7: VPPS Level 6 | G7: VPPS Level 7 | H7: VPPS Level 8 | I7: VPPS Level 9 | J7: Interfacing Component /Feature | K7: Component Designation | L7: Interface Designation | M7: Interface Type | N7: Change and Reason for Change
A8: Powertrain
B9: Power Generation
C10: Engine
D11: Accessory Drive System
E12: A Tensioner | J12: B Belt | M12: Mate
J13: G Tensioner Bracket | M13: Fastening
J14: A3 Belt Install Tool | M14: Clearance
E15: B Belt | J15: A Tensioner | M15: Mate
J16: B2 Front Cover | M16: Clearance
J17: B3 RH Engine Compartment Components | M17: Clearance
J18: C Idlers | M18: Mate
J19: E Power Steering Pump Pulley | M19: Mate
J20: D Water Pump Pulley | M20: Mate
J21: B4 A/C Compressor Pump Pulley | M21: Mate
J22: B5 Generator Pulley | M22: Mate
J23: B6 Crankshaft Pulley | M23: Mate
E24: C Idlers | J24: B Belt | M24: Mate
J25: C1 Water Cross-Over Pipe | M25: Fastening
J26: G Tensioner Bracket | M26: Fastening
J27: B2 Front Cover | M27: Clearance
E28: D Water Pump Pulley | J28: B Belt | M28: Mate
J29: D1 Water Pump Hub | M29: Fastening
J30: B2 Front Cover | M30: Clearance
J31: D2 Installation Tool | M31: Clearance
E32: E Power Steering Pump Pulley | J32: B Belt | M32: Mate
J33: E1 Power Steering Shaft | M33: Press-Fit
J34: E2 Power Steering Pump | M34: Clearance
J35: D2 Installation Tool | M35: Clearance
E36: F Generator Bracket | J36: F1 LH Cylinder Head | M36: Fastening
J37: F2 Intake Manifold | M37: Fastening
J38: F3 Generator | M38: Fastening
J39: F4 Fuel Rail | M39: Clearance
J40: F5 LH Cam Cover | M40: Clearance
E41: G Tensioner Bracket | J41: A Tensioner | M41: Fastening
...

Sheet Judgment Words
A1: Judgment Words
A3: Documents used for reports and presentations should contain only engineering results, facts, and judgments. These documents should not contain speculations, opinions, vague non descriptive words, or words with emotional connotations.
A4: Some examples of words or phrases that are to be avoided are listed below.
A5: Enter Judgment Words in column A below. Do not skip a row. Code will stop searching for words when an empty row is found.
A6: Judgment Words | B6: Suggestions
A7: annihilate
A8: apocalyptic
A9: asphyxiating
A10: bad
A11: Band-Aid
A12: biblical
A13: big time
A14: cataclysmic
A15: catastrophic
A16: Challenger
A17: chaotic
A18: Cobain
... A84: 安全

Sheet temp1
A1: L1/L2:电池仓-/底座- | B1: 13
A2: L1/L5:电池仓-/电池包- | B2: 14
A3: L2/L4:底座-/电机- | B3: 15
A4: L1/L3:电池仓-/电池仓盖- | B4: 16
A5: L2/L6:底座-/DECK- | B5: 17
A6: L4/L7:电机-/电机ＰＣＢ- | B6: 22
A7: L1/L8:电池仓-/电源管理ＰＣＢ- | B7: 23
A8: L4/L9:电机-/刀片系统- | B8: 25
A9: L1/L4:电池仓-/电机- | B9: 26
A10: L1/L10:电池仓-/把手组件- | B10: 28
A11: L1/L6:电池仓-/DECK- | B11: 29

Sheet temp2
A1: L1:电池仓- | B1: 41157
A2: L1:电池仓- | B2: 41157
A3: L1:电池仓- | B3: 41157
A4: L1:电池仓- | B4: 41157
A5: L1:电池仓- | B5: 41157
A6: L1:电池仓- | B6: 41157
A7: L1:电池仓- | B7: 41157
A8: L2:底座- | B8: 41158
A9: L2:底座- | B9: 41158
A10: L2:底座- | B10: 41158
A11: L3:电池仓盖- | B11: 41159
A12: L4:电机- | B12: 41160
... A15: L4:电机- | B15: 41160
